<?xml version="1.0"?>
<robot name="vine_robot">
  
  <!-- Describing the 3D motion of the vine Robot -->
  <link name="world"/>

  <joint name="Z" type="prismatic">
    <parent link="world"/>
    <child link="transitional_link"/>
    <origin xyz="0 0 0" rpy="0 0 0"/>
    <axis xyz="0 0 1"/> <!-- The direction of motion -->
    <limit lower="-5" upper="5" effort="1" velocity="1"/> <!-- The limits of the joint -->
  </joint>

  <link name="transitional_link"/>

  <joint name="Y" type="prismatic">
    <parent link="transitional_link"/>
    <child link="second_t_link"/>
    <origin xyz="0 0 0" rpy="0 0 0"/>
    <axis xyz="0 1 0"/> <!-- The direction of motion -->
    <limit lower="-5" upper="5" effort="1" velocity="1"/> <!-- The limits of the joint -->
  </joint>

  <link name="second_t_link"/>

  <joint name="X" type="prismatic">
    <parent link="second_t_link"/>
    <child link="head_link"/>
    <origin xyz="0 0 0" rpy="0 0 0"/>
    <axis xyz="1 0 0"/> <!-- The direction of motion -->
    <limit lower="-5" upper="5" effort="1" velocity="1"/> <!-- The limits of the joint -->
  </joint>

  <!-- Structure of Robot -->
  
  <link name="head_link">
  <visual>
    <origin xyz="0 0 0.0762" rpy="0 1.5707963268 0"/>
    <geometry>
      <cylinder length="0.15" radius="0.0762"/>
    </geometry>
    <material name="blue">
      <color rgba="0 0 1 1"/>
    </material>
  </visual>
  <collision>
    <origin xyz="0 0 0.0762" rpy="0 1.5707963268 0"/>
    <geometry>
      <cylinder length="0.15" radius="0.0762"/>
    </geometry>
  </collision>
  <inertial>
    <origin xyz="0 0 0.0762" rpy="0 1.5707963268 0"/>
    <mass value="0.01" />
    <inertia ixx="0.000019" ixy="0.0" ixz="0.0" iyy="0.000019" iyz="0.0" izz="0.000029" />
  </inertial>
</link>


  <joint name="camera_joint" type="fixed">
    <parent link="head_link"/>
    <child link="camera_link"/>
    <origin xyz="0.077 0 0.0762" rpy="0 1.5707963268 0"/>
  </joint>

  <link name="camera_link">
  <visual>
    <origin xyz="0 0 0" rpy=" 0 0 0"/>
    <geometry>
      <cylinder length="0.06" radius="0.0362"/>
    </geometry>
    <material name="red">
      <color rgba="1 0 0 1"/>
    </material>
  </visual>
  <collision>
    <origin xyz="0 0 0" rpy=" 0 0 0"/>
    <geometry>
      <cylinder length="0.06" radius="0.0362"/>
    </geometry>
  </collision>
  <inertial>
    <origin xyz="0 0 0" rpy=" 0 0 0"/>
    <mass value="0.001" />
    <inertia ixx="0.000000718" ixy="0.0" ixz="0.0" iyy="0.000000718" iyz="0.0" izz="0.0000006552" />
  </inertial>
</link>


</robot>
